<?xml version="1.0" ?>

<!--  Generates as follows: 
cd ~/plucky_ws/install/articubot_one/share/articubot_one/description
source ~/plucky_ws/install/setup.bash
xacro robot.urdf.xacro > robot.urdf
-->

<!-- =================================================================================== -->
<!-- |    This document was autogenerated by xacro from robot.urdf.xacro               | -->
<!-- |    EDITING THIS FILE BY HAND IS NOT RECOMMENDED                                 | -->
<!-- =================================================================================== -->
<robot name="robot">
  <!-- Specify some standard inertial calculations https://en.wikipedia.org/wiki/List_of_moments_of_inertia -->
  <!-- These make use of xacro's mathematical functionality -->
  <material name="white">
    <color rgba="1 1 1 1"/>
  </material>
  <material name="orange">
    <color rgba="1 0.3 0.1 1"/>
  </material>
  <material name="blue">
    <color rgba="0.2 0.2 1 1"/>
  </material>
  <material name="black">
    <color rgba="0 0 0 1"/>
  </material>
  <material name="red">
    <color rgba="1 0 0 1"/>
  </material>
  <!-- ****************** ROBOT BASE FOOTPRINT ***************************  -->
  <!-- Define the center of the main robot chassis projected on the ground -->
  <link name="base_footprint">
    </link>
  <!-- ********************** ROBOT BASE *********************************  -->
  <link name="base_link">
    </link>
  <!-- The base footprint of the robot is located underneath the chassis -->
  <joint name="base_joint" type="fixed">
    <parent link="base_footprint"/>
    <child link="base_link"/>
    <origin rpy="0 0 0" xyz="0 0 0.192"/>
  </joint>
  <!-- CHASSIS LINK -->
  <joint name="chassis_joint" type="fixed">
    <parent link="base_link"/>
    <child link="chassis"/>
    <origin xyz="-0.226 0 -0.01"/>
  </joint>
  <link name="chassis">
    <visual>
      <origin xyz="0.1675 0 0.069"/>
      <geometry>
        <box size="0.335 0.265 0.138"/>
      </geometry>
      <material name="orange"/>
    </visual>
    <collision>
      <origin xyz="0.1675 0 0.069"/>
      <geometry>
        <box size="0.335 0.265 0.138"/>
      </geometry>
    </collision>
    <inertial>
      <origin rpy="0 0 0" xyz="0.1675 0 0.069"/>
      <mass value="0.5"/>
      <inertia ixx="0.003719541666666667" ixy="0.0" ixz="0.0" iyy="0.005469541666666668" iyz="0.0" izz="0.007602083333333334"/>
    </inertial>
  </link>
  <gazebo reference="chassis">
    <material>Gazebo/Orange</material>
  </gazebo>
  <!-- *********************** IMU SETUP *********************************  -->
  <!-- Each sensor must be attached to a link.                              -->
  <link name="imu_link">
    <visual>
      <geometry>
        <box size="0.1 0.1 0.1"/>
      </geometry>
    </visual>
    <collision>
      <geometry>
        <box size="0.1 0.1 0.1"/>
      </geometry>
    </collision>
  </link>
  <joint name="imu_joint" type="fixed">
    <parent link="chassis"/>
    <child link="imu_link"/>
    <origin xyz="0 0 0.01"/>
  </joint>
  <!-- LEFT WHEEL LINK -->
  <joint name="left_wheel_joint" type="continuous">
    <parent link="base_link"/>
    <child link="left_wheel"/>
    <origin rpy="-1.5707963267948966 0 0" xyz="0 0.290 0"/>
    <axis xyz="0 0 1"/>
  </joint>
  <link name="left_wheel">
    <visual>
      <geometry>
        <cylinder length="0.026" radius="0.192"/>
      </geometry>
      <material name="blue"/>
    </visual>
    <collision>
      <geometry>
        <sphere radius="0.192"/>
      </geometry>
    </collision>
    <inertial>
      <origin rpy="0 0 0" xyz="0 0 0"/>
      <mass value="0.05"/>
      <inertia ixx="1.642916666666667e-05" ixy="0.0" ixz="0.0" iyy="1.642916666666667e-05" iyz="0.0" izz="2.7225000000000004e-05"/>
    </inertial>
  </link>
  <gazebo reference="left_wheel">
    <material>Gazebo/Blue</material>
  </gazebo>
  <!-- RIGHT WHEEL LINK -->
  <joint name="right_wheel_joint" type="continuous">
    <parent link="base_link"/>
    <child link="right_wheel"/>
    <origin rpy="1.5707963267948966 0 0" xyz="0 -0.290 0"/>
    <axis xyz="0 0 -1"/>
  </joint>
  <link name="right_wheel">
    <visual>
      <geometry>
        <cylinder length="0.026" radius="0.192"/>
      </geometry>
      <material name="blue"/>
    </visual>
    <collision>
      <geometry>
        <sphere radius="0.192"/>
      </geometry>
    </collision>
    <inertial>
      <origin rpy="0 0 0" xyz="0 0 0"/>
      <mass value="0.05"/>
      <inertia ixx="1.642916666666667e-05" ixy="0.0" ixz="0.0" iyy="1.642916666666667e-05" iyz="0.0" izz="2.7225000000000004e-05"/>
    </inertial>
  </link>
  <gazebo reference="right_wheel">
    <material>Gazebo/Blue</material>
  </gazebo>
  <!-- CASTER WHEEL LINK -->
  <joint name="caster_wheel_joint" type="fixed">
    <parent link="chassis"/>
    <child link="caster_wheel"/>
    <origin xyz="0.075 0 -0.013"/>
  </joint>
  <link name="caster_wheel">
    <visual>
      <geometry>
        <sphere radius="0.01"/>
      </geometry>
      <material name="white"/>
    </visual>
    <collision>
      <geometry>
        <sphere radius="0.01"/>
      </geometry>
    </collision>
    <inertial>
      <origin rpy="0 0 0" xyz="0 0 0"/>
      <mass value="0.01"/>
      <inertia ixx="4.0000000000000003e-07" ixy="0.0" ixz="0.0" iyy="4.0000000000000003e-07" iyz="0.0" izz="4.0000000000000003e-07"/>
    </inertial>
  </link>
  <gazebo reference="caster_wheel">
    <material>Gazebo/White</material>
    <mu1 value="0.001"/>
    <mu2 value="0.001"/>
  </gazebo>
  <ros2_control name="RealRobot" type="system">
    <hardware>
      <plugin>diffdrive_arduino/DiffDriveArduino</plugin>
      <param name="left_wheel_name">left_wheel_joint</param>
      <param name="right_wheel_name">right_wheel_joint</param>
      <param name="loop_rate">30</param>
      <param name="device">/dev/ttyACM0</param>
      <param name="baud_rate">115200</param>
      <param name="timeout">1000</param>
      <param name="enc_counts_per_rev">13730</param>
    </hardware>
    <joint name="left_wheel_joint">
      <command_interface name="velocity">
        <param name="min">-10</param>
        <param name="max">10</param>
      </command_interface>
      <state_interface name="velocity"/>
      <state_interface name="position"/>
    </joint>
    <joint name="right_wheel_joint">
      <command_interface name="velocity">
        <param name="min">-10</param>
        <param name="max">10</param>
      </command_interface>
      <state_interface name="velocity"/>
      <state_interface name="position"/>
    </joint>
  </ros2_control>
  <gazebo>
    <plugin filename="libgazebo_ros2_control.so" name="gazebo_ros2_control">
      <parameters>/home/sergei/plucky_ws/install/articubot_one/share/articubot_one/config/my_controllers.yaml</parameters>
      <parameters>/home/sergei/plucky_ws/install/articubot_one/share/articubot_one/config/gaz_ros2_ctl_use_sim.yaml</parameters>
    </plugin>
  </gazebo>
  <joint name="laser_joint" type="fixed">
    <parent link="chassis"/>
    <child link="laser_frame"/>
    <origin rpy="0 0 3.1459" xyz="0.122 0 0.212"/>
  </joint>
  <link name="laser_frame">
    <visual>
      <geometry>
        <cylinder length="0.04" radius="0.05"/>
      </geometry>
      <material name="black"/>
    </visual>
    <visual>
      <origin xyz="0 0 -0.05"/>
      <geometry>
        <cylinder length="0.1" radius="0.01"/>
      </geometry>
      <material name="black"/>
    </visual>
    <collision>
      <geometry>
        <cylinder length="0.04" radius="0.05"/>
      </geometry>
    </collision>
    <inertial>
      <origin rpy="0 0 0" xyz="0 0 0"/>
      <mass value="0.1"/>
      <inertia ixx="7.583333333333335e-05" ixy="0.0" ixz="0.0" iyy="7.583333333333335e-05" iyz="0.0" izz="0.00012500000000000003"/>
    </inertial>
  </link>
  <gazebo reference="laser_frame">
    <material>Gazebo/Black</material>
    <sensor name="laser" type="ray">
      <pose> 0 0 0 0 0 0 </pose>
      <visualize>false</visualize>
      <update_rate>10</update_rate>
      <ray>
        <scan>
          <horizontal>
            <samples>360</samples>
            <min_angle>-3.14</min_angle>
            <max_angle>3.14</max_angle>
          </horizontal>
        </scan>
        <range>
          <min>0.3</min>
          <max>12</max>
        </range>
      </ray>
      <plugin filename="libgazebo_ros_ray_sensor.so" name="laser_controller">
        <ros>
          <argument>~/out:=scan</argument>
        </ros>
        <output_type>sensor_msgs/LaserScan</output_type>
        <frame_name>laser_frame</frame_name>
      </plugin>
    </sensor>
  </gazebo>
  <joint name="camera_joint" type="fixed">
    <parent link="chassis"/>
    <child link="camera_link"/>
    <origin rpy="0 0.18 0" xyz="0.276 0 0.181"/>
  </joint>
  <link name="camera_link">
    <visual>
      <geometry>
        <box size="0.010 0.03 0.03"/>
      </geometry>
      <material name="black"/>
    </visual>
    <visual>
      <origin xyz="0 0 -0.05"/>
      <geometry>
        <cylinder length="0.1" radius="0.002"/>
      </geometry>
      <material name="black"/>
    </visual>
  </link>
  <joint name="camera_optical_joint" type="fixed">
    <parent link="camera_link"/>
    <child link="camera_link_optical"/>
    <origin rpy="-1.5707963267948966 0 -1.5707963267948966" xyz="0 0 0"/>
  </joint>
  <link name="camera_link_optical"/>
  <gazebo reference="camera_link">
    <material>Gazebo/Black</material>
    <sensor name="camera" type="camera">
      <pose> 0 0 0 0 0 0 </pose>
      <visualize>true</visualize>
      <update_rate>10</update_rate>
      <camera>
        <horizontal_fov>1.089</horizontal_fov>
        <image>
          <format>R8G8B8</format>
          <width>640</width>
          <height>480</height>
        </image>
        <clip>
          <near>0.05</near>
          <far>8.0</far>
        </clip>
      </camera>
      <plugin filename="libgazebo_ros_camera.so" name="camera_controller">
        <frame_name>camera_link_optical</frame_name>
      </plugin>
    </sensor>
  </gazebo>
  <!-- <xacro:include filename="depth_camera.xacro" /> -->
  <joint name="face_joint" type="fixed">
    <parent link="chassis"/>
    <child link="face_link"/>
    <origin rpy="0 0 0" xyz="0.335 0 0.069"/>
  </joint>
  <link name="face_link">
    <visual>
      <origin rpy="0 1.5707963267948966 0" xyz="0 0.05 0.01"/>
      <geometry>
        <cylinder length="0.002" radius="0.01"/>
      </geometry>
      <material name="black"/>
    </visual>
    <visual>
      <origin rpy="0 1.5707963267948966 0" xyz="0 -0.05 0.01"/>
      <geometry>
        <cylinder length="0.002" radius="0.01"/>
      </geometry>
      <material name="black"/>
    </visual>
    <visual>
      <origin rpy="0 1.5 0" xyz="-0.011 0 -0.00"/>
      <geometry>
        <cylinder length="0.02" radius="0.05"/>
      </geometry>
      <material name="red"/>
    </visual>
  </link>
  <gazebo reference="face_link">
    <material>Gazebo/Black</material>
  </gazebo>
</robot>
